Traceback (most recent call last):
  File "/opt/anaconda3/envs/py4ds2e/lib/python3.10/site-packages/jupyter_cache/executors/utils.py", line 58, in single_nb_execution
    executenb(
  File "/opt/anaconda3/envs/py4ds2e/lib/python3.10/site-packages/nbclient/client.py", line 1305, in execute
    return NotebookClient(nb=nb, resources=resources, km=km, **kwargs).execute()
  File "/opt/anaconda3/envs/py4ds2e/lib/python3.10/site-packages/jupyter_core/utils/__init__.py", line 166, in wrapped
    return loop.run_until_complete(inner)
  File "/opt/anaconda3/envs/py4ds2e/lib/python3.10/asyncio/base_events.py", line 649, in run_until_complete
    return future.result()
  File "/opt/anaconda3/envs/py4ds2e/lib/python3.10/site-packages/nbclient/client.py", line 705, in async_execute
    await self.async_execute_cell(
  File "/opt/anaconda3/envs/py4ds2e/lib/python3.10/site-packages/nbclient/client.py", line 1058, in async_execute_cell
    await self._check_raise_for_error(cell, cell_index, exec_reply)
  File "/opt/anaconda3/envs/py4ds2e/lib/python3.10/site-packages/nbclient/client.py", line 914, in _check_raise_for_error
    raise CellExecutionError.from_cell_and_msg(cell, exec_reply_content)
nbclient.exceptions.CellExecutionError: An error occurred while executing the following cell:
------------------
# remove-cell
import os

os.remove("output_chart.svg")
------------------


[0;31m---------------------------------------------------------------------------[0m
[0;31mFileNotFoundError[0m                         Traceback (most recent call last)
Input [0;32mIn [9][0m, in [0;36m<cell line: 4>[0;34m()[0m
[1;32m      1[0m [38;5;66;03m# remove-cell[39;00m
[1;32m      2[0m [38;5;28;01mimport[39;00m [38;5;21;01mos[39;00m
[0;32m----> 4[0m [43mos[49m[38;5;241;43m.[39;49m[43mremove[49m[43m([49m[38;5;124;43m"[39;49m[38;5;124;43moutput_chart.svg[39;49m[38;5;124;43m"[39;49m[43m)[49m

[0;31mFileNotFoundError[0m: [Errno 2] No such file or directory: 'output_chart.svg'

