Traceback (most recent call last):
  File "/opt/anaconda3/envs/py4ds2e/lib/python3.10/site-packages/jupyter_cache/executors/utils.py", line 58, in single_nb_execution
    executenb(
  File "/opt/anaconda3/envs/py4ds2e/lib/python3.10/site-packages/nbclient/client.py", line 1305, in execute
    return NotebookClient(nb=nb, resources=resources, km=km, **kwargs).execute()
  File "/opt/anaconda3/envs/py4ds2e/lib/python3.10/site-packages/jupyter_core/utils/__init__.py", line 166, in wrapped
    return loop.run_until_complete(inner)
  File "/opt/anaconda3/envs/py4ds2e/lib/python3.10/asyncio/base_events.py", line 649, in run_until_complete
    return future.result()
  File "/opt/anaconda3/envs/py4ds2e/lib/python3.10/site-packages/nbclient/client.py", line 705, in async_execute
    await self.async_execute_cell(
  File "/opt/anaconda3/envs/py4ds2e/lib/python3.10/site-packages/nbclient/client.py", line 1058, in async_execute_cell
    await self._check_raise_for_error(cell, cell_index, exec_reply)
  File "/opt/anaconda3/envs/py4ds2e/lib/python3.10/site-packages/nbclient/client.py", line 914, in _check_raise_for_error
    raise CellExecutionError.from_cell_and_msg(cell, exec_reply_content)
nbclient.exceptions.CellExecutionError: An error occurred while executing the following cell:
------------------
flights["time_hour"] = pd.to_datetime(flights["time_hour"], format="%Y-%m-%d %H:%M:%S")
------------------


[0;31m---------------------------------------------------------------------------[0m
[0;31mValueError[0m                                Traceback (most recent call last)
Input [0;32mIn [6][0m, in [0;36m<cell line: 1>[0;34m()[0m
[0;32m----> 1[0m flights[[38;5;124m"[39m[38;5;124mtime_hour[39m[38;5;124m"[39m] [38;5;241m=[39m [43mpd[49m[38;5;241;43m.[39;49m[43mto_datetime[49m[43m([49m[43mflights[49m[43m[[49m[38;5;124;43m"[39;49m[38;5;124;43mtime_hour[39;49m[38;5;124;43m"[39;49m[43m][49m[43m,[49m[43m [49m[38;5;28;43mformat[39;49m[38;5;241;43m=[39;49m[38;5;124;43m"[39;49m[38;5;124;43m%[39;49m[38;5;124;43mY-[39;49m[38;5;124;43m%[39;49m[38;5;124;43mm-[39;49m[38;5;132;43;01m%d[39;49;00m[38;5;124;43m [39;49m[38;5;124;43m%[39;49m[38;5;124;43mH:[39;49m[38;5;124;43m%[39;49m[38;5;124;43mM:[39;49m[38;5;124;43m%[39;49m[38;5;124;43mS[39;49m[38;5;124;43m"[39;49m[43m)[49m

File [0;32m/opt/anaconda3/envs/py4ds2e/lib/python3.10/site-packages/pandas/core/tools/datetimes.py:1046[0m, in [0;36mto_datetime[0;34m(arg, errors, dayfirst, yearfirst, utc, format, exact, unit, infer_datetime_format, origin, cache)[0m
[1;32m   1044[0m             result [38;5;241m=[39m arg[38;5;241m.[39mtz_localize([38;5;124m"[39m[38;5;124mutc[39m[38;5;124m"[39m)
[1;32m   1045[0m [38;5;28;01melif[39;00m [38;5;28misinstance[39m(arg, ABCSeries):
[0;32m-> 1046[0m     cache_array [38;5;241m=[39m [43m_maybe_cache[49m[43m([49m[43marg[49m[43m,[49m[43m [49m[38;5;28;43mformat[39;49m[43m,[49m[43m [49m[43mcache[49m[43m,[49m[43m [49m[43mconvert_listlike[49m[43m)[49m
[1;32m   1047[0m     [38;5;28;01mif[39;00m [38;5;129;01mnot[39;00m cache_array[38;5;241m.[39mempty:
[1;32m   1048[0m         result [38;5;241m=[39m arg[38;5;241m.[39mmap(cache_array)

File [0;32m/opt/anaconda3/envs/py4ds2e/lib/python3.10/site-packages/pandas/core/tools/datetimes.py:250[0m, in [0;36m_maybe_cache[0;34m(arg, format, cache, convert_listlike)[0m
[1;32m    248[0m unique_dates [38;5;241m=[39m unique(arg)
[1;32m    249[0m [38;5;28;01mif[39;00m [38;5;28mlen[39m(unique_dates) [38;5;241m<[39m [38;5;28mlen[39m(arg):
[0;32m--> 250[0m     cache_dates [38;5;241m=[39m [43mconvert_listlike[49m[43m([49m[43munique_dates[49m[43m,[49m[43m [49m[38;5;28;43mformat[39;49m[43m)[49m
[1;32m    251[0m     [38;5;66;03m# GH#45319[39;00m
[1;32m    252[0m     [38;5;28;01mtry[39;00m:

File [0;32m/opt/anaconda3/envs/py4ds2e/lib/python3.10/site-packages/pandas/core/tools/datetimes.py:453[0m, in [0;36m_convert_listlike_datetimes[0;34m(arg, format, name, utc, unit, errors, dayfirst, yearfirst, exact)[0m
[1;32m    451[0m [38;5;66;03m# `format` could be inferred, or user didn't ask for mixed-format parsing.[39;00m
[1;32m    452[0m [38;5;28;01mif[39;00m [38;5;28mformat[39m [38;5;129;01mis[39;00m [38;5;129;01mnot[39;00m [38;5;28;01mNone[39;00m [38;5;129;01mand[39;00m [38;5;28mformat[39m [38;5;241m!=[39m [38;5;124m"[39m[38;5;124mmixed[39m[38;5;124m"[39m:
[0;32m--> 453[0m     [38;5;28;01mreturn[39;00m [43m_array_strptime_with_fallback[49m[43m([49m[43marg[49m[43m,[49m[43m [49m[43mname[49m[43m,[49m[43m [49m[43mutc[49m[43m,[49m[43m [49m[38;5;28;43mformat[39;49m[43m,[49m[43m [49m[43mexact[49m[43m,[49m[43m [49m[43merrors[49m[43m)[49m
[1;32m    455[0m result, tz_parsed [38;5;241m=[39m objects_to_datetime64ns(
[1;32m    456[0m     arg,
[1;32m    457[0m     dayfirst[38;5;241m=[39mdayfirst,
[0;32m   (...)[0m
[1;32m    461[0m     allow_object[38;5;241m=[39m[38;5;28;01mTrue[39;00m,
[1;32m    462[0m )
[1;32m    464[0m [38;5;28;01mif[39;00m tz_parsed [38;5;129;01mis[39;00m [38;5;129;01mnot[39;00m [38;5;28;01mNone[39;00m:
[1;32m    465[0m     [38;5;66;03m# We can take a shortcut since the datetime64 numpy array[39;00m
[1;32m    466[0m     [38;5;66;03m# is in UTC[39;00m

File [0;32m/opt/anaconda3/envs/py4ds2e/lib/python3.10/site-packages/pandas/core/tools/datetimes.py:484[0m, in [0;36m_array_strptime_with_fallback[0;34m(arg, name, utc, fmt, exact, errors)[0m
[1;32m    473[0m [38;5;28;01mdef[39;00m [38;5;21m_array_strptime_with_fallback[39m(
[1;32m    474[0m     arg,
[1;32m    475[0m     name,
[0;32m   (...)[0m
[1;32m    479[0m     errors: [38;5;28mstr[39m,
[1;32m    480[0m ) [38;5;241m-[39m[38;5;241m>[39m Index:
[1;32m    481[0m [38;5;250m    [39m[38;5;124;03m"""[39;00m
[1;32m    482[0m [38;5;124;03m    Call array_strptime, with fallback behavior depending on 'errors'.[39;00m
[1;32m    483[0m [38;5;124;03m    """[39;00m
[0;32m--> 484[0m     result, timezones [38;5;241m=[39m [43marray_strptime[49m[43m([49m[43marg[49m[43m,[49m[43m [49m[43mfmt[49m[43m,[49m[43m [49m[43mexact[49m[38;5;241;43m=[39;49m[43mexact[49m[43m,[49m[43m [49m[43merrors[49m[38;5;241;43m=[39;49m[43merrors[49m[43m,[49m[43m [49m[43mutc[49m[38;5;241;43m=[39;49m[43mutc[49m[43m)[49m
[1;32m    485[0m     [38;5;28;01mif[39;00m [38;5;28many[39m(tz [38;5;129;01mis[39;00m [38;5;129;01mnot[39;00m [38;5;28;01mNone[39;00m [38;5;28;01mfor[39;00m tz [38;5;129;01min[39;00m timezones):
[1;32m    486[0m         [38;5;28;01mreturn[39;00m _return_parsed_timezone_results(result, timezones, utc, name)

File [0;32m/opt/anaconda3/envs/py4ds2e/lib/python3.10/site-packages/pandas/_libs/tslibs/strptime.pyx:530[0m, in [0;36mpandas._libs.tslibs.strptime.array_strptime[0;34m()[0m

File [0;32m/opt/anaconda3/envs/py4ds2e/lib/python3.10/site-packages/pandas/_libs/tslibs/strptime.pyx:351[0m, in [0;36mpandas._libs.tslibs.strptime.array_strptime[0;34m()[0m

[0;31mValueError[0m: time data "2013-01-01T10:00:00Z" doesn't match format "%Y-%m-%d %H:%M:%S", at position 0. You might want to try:
    - passing `format` if your strings have a consistent format;
    - passing `format='ISO8601'` if your strings are all ISO8601 but not necessarily in exactly the same format;
    - passing `format='mixed'`, and the format will be inferred for each element individually. You might want to use `dayfirst` alongside this.

