Traceback (most recent call last):
  File "/opt/anaconda3/envs/py4ds2e/lib/python3.10/site-packages/jupyter_cache/executors/utils.py", line 58, in single_nb_execution
    executenb(
  File "/opt/anaconda3/envs/py4ds2e/lib/python3.10/site-packages/nbclient/client.py", line 1305, in execute
    return NotebookClient(nb=nb, resources=resources, km=km, **kwargs).execute()
  File "/opt/anaconda3/envs/py4ds2e/lib/python3.10/site-packages/jupyter_core/utils/__init__.py", line 166, in wrapped
    return loop.run_until_complete(inner)
  File "/opt/anaconda3/envs/py4ds2e/lib/python3.10/asyncio/base_events.py", line 649, in run_until_complete
    return future.result()
  File "/opt/anaconda3/envs/py4ds2e/lib/python3.10/site-packages/nbclient/client.py", line 705, in async_execute
    await self.async_execute_cell(
  File "/opt/anaconda3/envs/py4ds2e/lib/python3.10/site-packages/nbclient/client.py", line 1058, in async_execute_cell
    await self._check_raise_for_error(cell, cell_index, exec_reply)
  File "/opt/anaconda3/envs/py4ds2e/lib/python3.10/site-packages/nbclient/client.py", line 914, in _check_raise_for_error
    raise CellExecutionError.from_cell_and_msg(cell, exec_reply_content)
nbclient.exceptions.CellExecutionError: An error occurred while executing the following cell:
------------------
import pandas as pd
from lets_plot import *
from lets_plot.geo_data import *
from lets_plot.mapping import as_discrete

LetsPlot.setup_html()
------------------


[0;31m---------------------------------------------------------------------------[0m
[0;31mValueError[0m                                Traceback (most recent call last)
Input [0;32mIn [1][0m, in [0;36m<cell line: 3>[0;34m()[0m
[1;32m      1[0m [38;5;28;01mimport[39;00m [38;5;21;01mpandas[39;00m [38;5;28;01mas[39;00m [38;5;21;01mpd[39;00m
[1;32m      2[0m [38;5;28;01mfrom[39;00m [38;5;21;01mlets_plot[39;00m [38;5;28;01mimport[39;00m [38;5;241m*[39m
[0;32m----> 3[0m [38;5;28;01mfrom[39;00m [38;5;21;01mlets_plot[39;00m[38;5;21;01m.[39;00m[38;5;21;01mgeo_data[39;00m [38;5;28;01mimport[39;00m [38;5;241m*[39m
[1;32m      4[0m [38;5;28;01mfrom[39;00m [38;5;21;01mlets_plot[39;00m[38;5;21;01m.[39;00m[38;5;21;01mmapping[39;00m [38;5;28;01mimport[39;00m as_discrete
[1;32m      6[0m LetsPlot[38;5;241m.[39msetup_html()

File [0;32m/opt/anaconda3/envs/py4ds2e/lib/python3.10/site-packages/lets_plot/geo_data/__init__.py:4[0m, in [0;36m<module>[0;34m[0m
[1;32m      2[0m     [38;5;28;01mimport[39;00m [38;5;21;01mgeopandas[39;00m
[1;32m      3[0m [38;5;28;01mexcept[39;00m [38;5;167;01mImportError[39;00m:
[0;32m----> 4[0m     [38;5;28;01mraise[39;00m [38;5;167;01mValueError[39;00m([38;5;124m"[39m[38;5;124mgeopandas is required for using the geo_data package[39m[38;5;124m"[39m) [38;5;28;01mfrom[39;00m [38;5;28;01mNone[39;00m
[1;32m      6[0m [38;5;28;01mfrom[39;00m [38;5;21;01m.[39;00m[38;5;21;01mcore[39;00m [38;5;28;01mimport[39;00m [38;5;241m*[39m
[1;32m      7[0m [38;5;28;01mfrom[39;00m [38;5;21;01m.[39;00m[38;5;21;01mgeocoder[39;00m [38;5;28;01mimport[39;00m [38;5;241m*[39m

[0;31mValueError[0m: geopandas is required for using the geo_data package

