Traceback (most recent call last):
  File "/opt/anaconda3/envs/py4ds2e/lib/python3.10/site-packages/jupyter_cache/executors/utils.py", line 58, in single_nb_execution
    executenb(
  File "/opt/anaconda3/envs/py4ds2e/lib/python3.10/site-packages/nbclient/client.py", line 1305, in execute
    return NotebookClient(nb=nb, resources=resources, km=km, **kwargs).execute()
  File "/opt/anaconda3/envs/py4ds2e/lib/python3.10/site-packages/jupyter_core/utils/__init__.py", line 166, in wrapped
    return loop.run_until_complete(inner)
  File "/opt/anaconda3/envs/py4ds2e/lib/python3.10/asyncio/base_events.py", line 649, in run_until_complete
    return future.result()
  File "/opt/anaconda3/envs/py4ds2e/lib/python3.10/site-packages/nbclient/client.py", line 705, in async_execute
    await self.async_execute_cell(
  File "/opt/anaconda3/envs/py4ds2e/lib/python3.10/site-packages/nbclient/client.py", line 1058, in async_execute_cell
    await self._check_raise_for_error(cell, cell_index, exec_reply)
  File "/opt/anaconda3/envs/py4ds2e/lib/python3.10/site-packages/nbclient/client.py", line 914, in _check_raise_for_error
    raise CellExecutionError.from_cell_and_msg(cell, exec_reply_content)
nbclient.exceptions.CellExecutionError: An error occurred while executing the following cell:
------------------
import matplotlib_inline.backend_inline

matplotlib_inline.backend_inline.set_matplotlib_formats("svg")
------------------


[0;31m---------------------------------------------------------------------------[0m
[0;31mModuleNotFoundError[0m                       Traceback (most recent call last)
Input [0;32mIn [1][0m, in [0;36m<cell line: 1>[0;34m()[0m
[0;32m----> 1[0m [38;5;28;01mimport[39;00m [38;5;21;01mmatplotlib_inline[39;00m[38;5;21;01m.[39;00m[38;5;21;01mbackend_inline[39;00m
[1;32m      3[0m matplotlib_inline[38;5;241m.[39mbackend_inline[38;5;241m.[39mset_matplotlib_formats([38;5;124m"[39m[38;5;124msvg[39m[38;5;124m"[39m)

File [0;32m/opt/anaconda3/envs/py4ds2e/lib/python3.10/site-packages/matplotlib_inline/__init__.py:1[0m, in [0;36m<module>[0;34m[0m
[0;32m----> 1[0m [38;5;28;01mfrom[39;00m [38;5;21;01m.[39;00m [38;5;28;01mimport[39;00m backend_inline, config  [38;5;66;03m# noqa[39;00m
[1;32m      2[0m __version__ [38;5;241m=[39m [38;5;124m"[39m[38;5;124m0.1.6[39m[38;5;124m"[39m  [38;5;66;03m# noqa[39;00m

File [0;32m/opt/anaconda3/envs/py4ds2e/lib/python3.10/site-packages/matplotlib_inline/backend_inline.py:6[0m, in [0;36m<module>[0;34m[0m
[1;32m      1[0m [38;5;124;03m"""A matplotlib backend for publishing figures via display_data"""[39;00m
[1;32m      3[0m [38;5;66;03m# Copyright (c) IPython Development Team.[39;00m
[1;32m      4[0m [38;5;66;03m# Distributed under the terms of the BSD 3-Clause License.[39;00m
[0;32m----> 6[0m [38;5;28;01mimport[39;00m [38;5;21;01mmatplotlib[39;00m
[1;32m      7[0m [38;5;28;01mfrom[39;00m [38;5;21;01mmatplotlib[39;00m [38;5;28;01mimport[39;00m colors
[1;32m      8[0m [38;5;28;01mfrom[39;00m [38;5;21;01mmatplotlib[39;00m[38;5;21;01m.[39;00m[38;5;21;01mbackends[39;00m [38;5;28;01mimport[39;00m backend_agg

[0;31mModuleNotFoundError[0m: No module named 'matplotlib'

